C:\Users\AnilNM\PycharmProjects\pythonProject\venv\Scripts\python.exe "C:/Program Files/JetBrains/PyCharm Community Edition 2022.2.2/plugins/python-ce/helpers/pydev/pydevd.py" --multiprocess --qt-support=auto --client 127.0.0.1 --port 60611 --file "C:/Program Files/JetBrains/PyCharm Community Edition 2022.2.2/plugins/python-ce/helpers/pycharm/_jb_pytest_runner.py" --path C:\Users\AnilNM\PycharmProjects\pythonProject\venv\test_github_operations_pytest.py -- --jb-show-summary 
Testing started at 9:44 PM ...
Launching pytest with arguments C:\Users\AnilNM\PycharmProjects\pythonProject\venv\test_github_operations_pytest.py in C:\Users\AnilNM\PycharmProjects\pythonProject\venv

============================= test session starts =============================
platform win32 -- Python 3.9.13, pytest-7.1.3, pluggy-1.0.0 -- C:\Users\AnilNM\PycharmProjects\pythonProject\venv\Scripts\python.exe
cachedir: .pytest_cache
rootdir: C:\Users\AnilNM\PycharmProjects\pythonProject\venv
collecting ... collected 4 items

test_github_operations_pytest.py::test_login_and_create_repo PASSED      [ 25%]
test_github_operations_pytest.py::test_push_readme_file_for_new_repo PASSED [ 50%]Reinitialized existing Git repository in C:/Users/AnilNM/PycharmProjects/pythonProject/venv/.git/
[main eb73905] first commit
 1 file changed, 1 insertion(+), 1 deletion(-)
error: remote origin already exists.
To https://github.com/anilnm/git_flow_task-20221023-214438.git
 * [new branch]      main -> main

test_github_operations_pytest.py::test_create_new_branch PASSED          [ 75%]
test_github_operations_pytest.py::test_commit_new_file_and_create_pull_to_master PASSED [100%][git_flow_feature 48fc076] Committing sample.txt to git_flow_feature
 1 file changed, 1 insertion(+)
 create mode 100644 sample.txt
To https://github.com/anilnm/git_flow_task-20221023-214438.git
   eb73905..48fc076  git_flow_feature -> git_flow_feature


======================== 4 passed in 138.43s (0:02:18) ========================

Process finished with exit code 0
